<?xml version="1.0" ?>
<!-- =================================================================================== -->
<!-- |    This document was autogenerated by xacro from green_jazzy.xacro              | -->
<!-- |    EDITING THIS FILE BY HAND IS NOT RECOMMENDED                                 | -->
<!-- =================================================================================== -->
<robot name="green_description">
  <!-- <xacro:property name="base_mass" value="63.5" /> -->
  <!-- Robot description -->
  <!-- Base Footprint -->
  <!-- <link name="base_footprint">
        <xacro:box_inertia m="8" w="0.001" d="0.001" h="0.001"/>
        <visual>
          <origin xyz="0 0 0" rpy="0 0 0" />
            <geometry>
                <box size="0.001 0.001 0.001" />
            </geometry>
        </visual>
    </link>  -->
  <!-- <gazebo reference="base_footprint">
        <material>Gazebo/white</material>
    </gazebo> -->
  <plugin filename="ignition-gazebo-pose-publisher-system" name="ignition::gazebo::systems::PosePublisher">
    <publish_link_pose>true</publish_link_pose>
    <publish_model_pose>true</publish_model_pose>
    <use_pose_vector_msg>true</use_pose_vector_msg>
    <static_publisher>false</static_publisher>
    <update_frequency>20</update_frequency>
  </plugin>
  <!-- Base Link -->
  <link name="base_link">
    <inertial>
      <origin rpy="0 0 0" xyz="0.25299 0 0.265"/>
      <mass value="63.5"/>
      <inertia ixx="5.308864583333333" ixy="0.0" ixz="0.0" iyy="5.993473958333333" iyz="0.0" izz="5.308864583333333"/>
    </inertial>
    <visual>
      <origin rpy="0 0 0" xyz="0.31299 0.0 -0.08"/>
      <geometry>
        <mesh filename="package://lognave_isaac/urdf/meshes/tractor.stl"/>
      </geometry>
    </visual>
    <collision>
      <origin rpy="0 0 -1.57" xyz="0.25299 0 0.265"/>
      <geometry>
        <box size="0.505 0.865 0.62"/>
      </geometry>
    </collision>
  </link>
  <gazebo reference="base_link">
    <material>Gazebo/Green</material>
  </gazebo>
  <!-- 
    <joint name="base_link_joint" type="fixed">
        <origin xyz="0.0 0.0 0.0" rpy="0 0 0"/>
        <parent link="base_footprint"/>
        <child link="base_link"/>
    </joint>     -->
  <!-- Front Fork -->
  <link name="front_fork">
    <inertial>
      <origin rpy="0 0 0" xyz="0 0 0"/>
      <mass value="1.0"/>
      <inertia ixx="0.0010000000000000002" ixy="0.0" ixz="0.0" iyy="0.0010000000000000002" iyz="0.0" izz="0.0010000000000000002"/>
    </inertial>
    <visual>
      <origin rpy="0 1.57 0" xyz="0 0 -0.05"/>
      <geometry>
        <mesh filename="package://lognave_isaac/urdf/meshes/front_fork.stl"/>
      </geometry>
    </visual>
    <!-- <collision>
             <origin xyz="0 0 0" rpy="1.57 0 0" />
             <geometry>
                <sphere radius="${fork_radius}"/>
            </geometry>   
        </collision> -->
  </link>
  <gazebo reference="front_fork">
    <material>Gazebo/Green</material>
  </gazebo>
  <joint name="front_fork_joint" type="continuous">
    <origin rpy="0 -1.5 0" xyz="0.44 0.0 -0.05"/>
    <parent link="base_link"/>
    <child link="front_fork"/>
    <axis xyz="0 0 1"/>
    <calibration falling="0" rising="0"/>
    <dynamics damping="0.00" friction="0.0"/>
    <safety_controller k_position="0" k_velocity="0" soft_lower="0" soft_upper="0"/>
  </joint>
  <!-- Front Wheel -->
  <link name="front_wheel">
    <inertial>
      <origin rpy="0 0 0" xyz="0 0 0"/>
      <mass value="1.0"/>
      <inertia ixx="0.0010000000000000002" ixy="0.0" ixz="0.0" iyy="0.0010000000000000002" iyz="0.0" izz="0.0010000000000000002"/>
    </inertial>
    <visual>
      <origin rpy="0 0 0" xyz="0 0 0"/>
      <geometry>
        <mesh filename="package://lognave_isaac/urdf/meshes/front_wheel.stl"/>
      </geometry>
    </visual>
    <collision>
      <origin rpy="0 0 0" xyz="0 0 0"/>
      <geometry>
        <sphere radius="0.05"/>
      </geometry>
    </collision>
  </link>
  <gazebo reference="front_wheel">
    <material>Gazebo/Black</material>
  </gazebo>
  <joint name="front_wheel_joint" type="continuous">
    <origin rpy="0 0 0" xyz="0.02 0 -0.005"/>
    <parent link="front_fork"/>
    <child link="front_wheel"/>
    <axis xyz="0 1 0"/>
    <calibration falling="0" rising="0"/>
    <dynamics damping="0.00" friction="0.0"/>
    <safety_controller k_position="0" k_velocity="0" soft_lower="0" soft_upper="0"/>
  </joint>
  <link name="left_rear_wheel">
    <inertial>
      <origin rpy="0 0 0" xyz="0 0 0"/>
      <mass value="1.0"/>
      <inertia ixx="0.00225" ixy="0.0" ixz="0.0" iyy="0.00225" iyz="0.0" izz="0.00225"/>
    </inertial>
    <visual>
      <origin rpy="0 0 0" xyz="0 0 0"/>
      <geometry>
        <mesh filename="package://lognave_isaac/urdf/meshes/right_rear_wheel.stl"/>
      </geometry>
    </visual>
    <collision>
      <origin rpy="0 0 0" xyz="0 0.075 0"/>
      <geometry>
        <sphere radius="0.075"/>
      </geometry>
    </collision>
  </link>
  <gazebo reference="left_rear_wheel">
    <material>Gazebo/Black</material>
  </gazebo>
  <joint name="left_rear_wheel_joint" type="continuous">
    <origin rpy="0 0 0" xyz="0 -0.075 0"/>
    <parent link="base_link"/>
    <child link="left_rear_wheel"/>
    <axis xyz="0 1 0"/>
    <calibration falling="0" rising="0"/>
    <dynamics damping="0.00" friction="0.0"/>
    <safety_controller k_position="0" k_velocity="0" soft_lower="0" soft_upper="0"/>
  </joint>
  <link name="right_rear_wheel">
    <inertial>
      <origin rpy="0 0 0" xyz="0 0 0"/>
      <mass value="1.0"/>
      <inertia ixx="0.00225" ixy="0.0" ixz="0.0" iyy="0.00225" iyz="0.0" izz="0.00225"/>
    </inertial>
    <visual>
      <origin rpy="0 0 3.14" xyz="0 0 0"/>
      <geometry>
        <mesh filename="package://lognave_isaac/urdf/meshes/right_rear_wheel.stl"/>
      </geometry>
    </visual>
    <collision>
      <origin rpy="0 0 0" xyz="0 -0.075 0"/>
      <geometry>
        <sphere radius="0.075"/>
      </geometry>
    </collision>
  </link>
  <gazebo reference="right_rear_wheel">
    <material>Gazebo/Black</material>
  </gazebo>
  <joint name="right_rear_wheel_joint" type="continuous">
    <origin rpy="0 0 0" xyz="0 0.075 0"/>
    <parent link="base_link"/>
    <child link="right_rear_wheel"/>
    <axis xyz="0 1 0"/>
    <calibration falling="0" rising="0"/>
    <dynamics damping="0.00" friction="0.0"/>
    <safety_controller k_position="0" k_velocity="0" soft_lower="0" soft_upper="0"/>
  </joint>
  <joint name="camera_joint" type="fixed">
    <parent link="base_link"/>
    <child link="camera_link"/>
    <origin rpy="0 0 -1.57" xyz="0.61299 0.0 0.29"/>
  </joint>
  <link name="camera_link">
    <inertial>
      <origin rpy="0 0 0" xyz="0 0 0"/>
      <mass value="1"/>
      <inertia ixx="0.004000000000000001" ixy="0.0" ixz="0.0" iyy="0.004000000000000001" iyz="0.0" izz="0.004000000000000001"/>
    </inertial>
    <visual>
      <origin rpy="0 0 0" xyz="0 0 0"/>
      <geometry>
        <sphere radius="0.01"/>
      </geometry>
      <material name="">
        <color rgba="0.29804 0.29804 0.29804 1"/>
      </material>
    </visual>
    <collision>
      <origin rpy="0 0 0" xyz="0 0 0"/>
      <geometry>
        <sphere radius="0.01"/>
      </geometry>
    </collision>
  </link>
  <joint name="camera_optical_joint" type="fixed">
    <parent link="camera_link"/>
    <child link="camera_link_optical"/>
    <origin rpy="0 0 1.5708" xyz="0 0 0"/>
  </joint>
  <link name="camera_link_optical"/>
  <!-- Camera Gazebo Sensor Plugin -->
  <gazebo reference="camera_link">
    <material>Gazebo/Black</material>
    <sensor name="rgbd_camera" type="rgbd_camera">
      <pose> 0 0 0 0 0 1.5708 </pose>
      <always_on>true</always_on>
      <visualize>true</visualize>
      <update_rate>30</update_rate>
      <topic>camera</topic>
      <gz_frame_id>camera_link</gz_frame_id>
      <camera>
        <optical_frame_id>camera_link_optical</optical_frame_id>
        <camera_info_topic>camera/camera_info</camera_info_topic>
        <horizontal_fov>1.089</horizontal_fov>
        <image>
          <format>R8G8B8</format>
          <width>640</width>
          <height>480</height>
        </image>
        <clip>
          <near>0.05</near>
          <far>30.0</far>
        </clip>
      </camera>
    </sensor>
  </gazebo>
  <joint name="laser_joint" type="fixed">
    <parent link="base_link"/>
    <child link="laser_frame"/>
    <origin rpy="0 0 0" xyz="0.61299 0.0 0.69"/>
  </joint>
  <link name="laser_frame">
    <inertial>
      <origin rpy="0 0 0" xyz="0 0 0"/>
      <mass value="1"/>
      <inertia ixx="0.004000000000000001" ixy="0.0" ixz="0.0" iyy="0.004000000000000001" iyz="0.0" izz="0.004000000000000001"/>
    </inertial>
    <visual>
      <origin rpy="0 0 0" xyz="0 0 0"/>
      <geometry>
        <sphere radius="0.01"/>
      </geometry>
      <material name="">
        <color rgba="0.29804 0.29804 0.29804 1"/>
      </material>
    </visual>
    <collision>
      <origin rpy="0 0 0" xyz="0 0 0"/>
      <geometry>
        <sphere radius="0.01"/>
      </geometry>
    </collision>
  </link>
  <gazebo reference="laser_frame">
    <material>Gazebo/Black</material>
    <sensor name="laser" type="gpu_lidar">
      <pose> 0 0 0 0 0 0 </pose>
      <visualize>false</visualize>
      <update_rate>10</update_rate>
      <lidar>
        <scan>
          <horizontal>
            <samples>440</samples>
            <resolution>1</resolution>
            <min_angle>-1.57</min_angle>
            <max_angle>1.57</max_angle>
          </horizontal>
          <vertical>
            <samples>16</samples>
            <resolution>1</resolution>
            <min_angle>-0.261799</min_angle>
            <max_angle>0.261799</max_angle>
          </vertical>
        </scan>
        <range>
          <min>0.5</min>
          <max>100</max>
          <resolution>0.001</resolution>
        </range>
      </lidar>
      <topic>points</topic>
      <gz_frame_id>laser_frame</gz_frame_id>
    </sensor>
  </gazebo>
  <link name="imu_link">
    <visual name="imu_visual">
      <geometry>
        <box size="0.01 0.01 0.01"/>
      </geometry>
    </visual>
    <inertial>
      <mass value="0.001"/>
      <inertia ixx="1.6666666666666669e-06" ixy="0.0" ixz="0.0" iyy="8.453333333333335e-07" iyz="0.0" izz="1.6666666666666669e-06"/>
    </inertial>
  </link>
  <joint name="imu_joint" type="fixed">
    <parent link="base_link"/>
    <child link="imu_link"/>
    <origin rpy="0 0 0" xyz="0 0 0"/>
  </joint>
  <gazebo reference="imu_link">
    <sensor name="imu_sensor" type="imu">
      <always_on>1</always_on>
      <update_rate>50</update_rate>
      <imu>
        <enable_orientation>0</enable_orientation>
        <angular_velocity>
          <x>
            <noise type="gaussian">
              <mean>0</mean>
              <stddev>0.009</stddev>
              <bias_mean>0.00075</bias_mean>
              <bias_stddev>0.005</bias_stddev>
              <dynamic_bias_stddev>0.00002</dynamic_bias_stddev>
              <dynamic_bias_correlation_time>400.0</dynamic_bias_correlation_time>
              <precision>0.00025</precision>
            </noise>
          </x>
          <y>
            <noise type="gaussian">
              <mean>0</mean>
              <stddev>0.009</stddev>
              <bias_mean>0.00075</bias_mean>
              <bias_stddev>0.005</bias_stddev>
              <dynamic_bias_stddev>0.00002</dynamic_bias_stddev>
              <dynamic_bias_correlation_time>400.0</dynamic_bias_correlation_time>
              <precision>0.00025</precision>
            </noise>
          </y>
          <z>
            <noise type="gaussian">
              <mean>0</mean>
              <stddev>0.009</stddev>
              <bias_mean>0.00075</bias_mean>
              <bias_stddev>0.005</bias_stddev>
              <dynamic_bias_stddev>0.00002</dynamic_bias_stddev>
              <dynamic_bias_correlation_time>400.0</dynamic_bias_correlation_time>
              <precision>0.00025</precision>
            </noise>
          </z>
        </angular_velocity>
        <linear_acceleration>
          <x>
            <noise type="gaussian">
              <mean>0</mean>
              <stddev>0.021</stddev>
              <bias_mean>0.05</bias_mean>
              <bias_stddev>0.0075</bias_stddev>
              <dynamic_bias_stddev>0.000375</dynamic_bias_stddev>
              <dynamic_bias_correlation_time>175.0</dynamic_bias_correlation_time>
              <precision>0.005</precision>
            </noise>
          </x>
          <y>
            <noise type="gaussian">
              <mean>0</mean>
              <stddev>0.021</stddev>
              <bias_mean>0.05</bias_mean>
              <bias_stddev>0.0075</bias_stddev>
              <dynamic_bias_stddev>0.000375</dynamic_bias_stddev>
              <dynamic_bias_correlation_time>175.0</dynamic_bias_correlation_time>
              <precision>0.005</precision>
            </noise>
          </y>
          <z>
            <noise type="gaussian">
              <mean>0</mean>
              <stddev>0.021</stddev>
              <bias_mean>0.05</bias_mean>
              <bias_stddev>0.0075</bias_stddev>
              <dynamic_bias_stddev>0.000375</dynamic_bias_stddev>
              <dynamic_bias_correlation_time>175.0</dynamic_bias_correlation_time>
              <precision>0.005</precision>
            </noise>
          </z>
        </linear_acceleration>
      </imu>
      <topic>imu</topic>
      <gz_frame_id>imu_link</gz_frame_id>
    </sensor>
  </gazebo>
  <ros2_control name="GazeboSimSystem" type="system">
    <hardware>
      <plugin>gz_ros2_control/GazeboSimSystem</plugin>
    </hardware>
    <joint name="right_rear_wheel_joint">
      <command_interface name="velocity">
        <param name="min">-1</param>
        <param name="max">1</param>
      </command_interface>
      <state_interface name="velocity"/>
      <state_interface name="position"/>
    </joint>
    <joint name="left_rear_wheel_joint">
      <command_interface name="velocity">
        <param name="min">-1</param>
        <param name="max">1</param>
      </command_interface>
      <state_interface name="velocity"/>
      <state_interface name="position"/>
    </joint>
    <joint name="front_fork_joint">
      <state_interface name="velocity"/>
      <state_interface name="position"/>
    </joint>
    <joint name="front_wheel_joint">
      <state_interface name="velocity"/>
      <state_interface name="position"/>
    </joint>
  </ros2_control>
  <gazebo>
    <plugin filename="gz_ros2_control-system" name="gz_ros2_control::GazeboSimROS2ControlPlugin">
      <!--<robot_sim_type>gazebo_ros2_control/GazeboSystem</robot_sim_type>
          <robot_param>robot_description</robot_param>
          <robot_namespace>freedom_vehicle</robot_namespace>
          <robot_param_node>robot_state_publisher</robot_param_node>-->
      <parameters>/home/kriskappel/lognav/lognav_simulation/config/green_jazzy_controllers.yaml</parameters>
    </plugin>
  </gazebo>
  <!-- Front Rplidar-->
  <link name="front_rplidar_link">
    <collision>
      <geometry>
        <cylinder length="0.02" radius="0.035"/>
      </geometry>
      <origin rpy="0 0 0" xyz="0 0 0.01"/>
    </collision>
    <visual>
      <geometry>
        <cylinder length="0.02" radius="0.035"/>
      </geometry>
      <material name="dark_gray">
        <color rgba="0.2 0.2 0.2 1"/>
      </material>
      <origin rpy="0 0 0" xyz="0 0 0.01"/>
    </visual>
    <inertial>
      <mass value="0.2"/>
      <origin rpy="0 0 0" xyz="0 0 0.01"/>
      <inertia ixx="0.001" ixy="0.0" ixz="0.0" iyy="0.001" iyz="0.0" izz="0.001"/>
    </inertial>
  </link>
  <joint name="front_rplidar_joint" type="fixed">
    <parent link="base_link"/>
    <child link="front_rplidar_link"/>
    <origin rpy="0 0 0" xyz="0.59299 0.19 0.09"/>
  </joint>
  <gazebo reference="front_rplidar_link">
    <material>Gazebo/Black</material>
    <sensor name="laser1" type="gpu_lidar">
      <pose> 0 0 0 0 0 0 </pose>
      <visualize>false</visualize>
      <update_rate>10</update_rate>
      <lidar>
        <scan>
          <horizontal>
            <samples>440</samples>
            <!-- originally 1200 samples -->
            <resolution>1</resolution>
            <min_angle>-1.25</min_angle>
            <max_angle>2.6</max_angle>
          </horizontal>
        </scan>
        <range>
          <min>0.2</min>
          <max>12</max>
          <resolution>0.01</resolution>
        </range>
      </lidar>
      <topic>scan1</topic>
      <gz_frame_id>front_rplidar_link</gz_frame_id>
    </sensor>
  </gazebo>
  <!-- Rear Rplidar-->
  <link name="rear_rplidar_link">
    <collision>
      <geometry>
        <cylinder length="0.02" radius="0.035"/>
      </geometry>
      <origin rpy="0 0 0" xyz="0 0 0.01"/>
    </collision>
    <visual>
      <geometry>
        <cylinder length="0.02" radius="0.035"/>
      </geometry>
      <material name="dark_gray">
        <color rgba="0.2 0.2 0.2 1"/>
      </material>
      <origin rpy="0 0 0" xyz="0 0 0.01"/>
    </visual>
    <inertial>
      <mass value="0.2"/>
      <origin rpy="0 0 0" xyz="0 0 0.01"/>
      <inertia ixx="0.001" ixy="0.0" ixz="0.0" iyy="0.001" iyz="0.0" izz="0.001"/>
    </inertial>
  </link>
  <joint name="rear_rplidar_joint" type="fixed">
    <parent link="base_link"/>
    <child link="rear_rplidar_link"/>
    <origin rpy="0 0 -1.57" xyz="-0.10701 -0.19 0.09"/>
  </joint>
  <gazebo reference="rear_rplidar_link">
    <material>Gazebo/Black</material>
    <sensor name="laser2" type="gpu_lidar">
      <pose> 0 0 0 0 0 0 </pose>
      <visualize>false</visualize>
      <update_rate>10</update_rate>
      <lidar>
        <scan>
          <horizontal>
            <samples>440</samples>
            <!-- originally 1200 samples -->
            <resolution>1</resolution>
            <min_angle>-2.6</min_angle>
            <max_angle>1.25</max_angle>
          </horizontal>
        </scan>
        <range>
          <min>0.2</min>
          <max>12</max>
          <resolution>0.01</resolution>
        </range>
      </lidar>
      <topic>scan2</topic>
      <gz_frame_id>rear_rplidar_link</gz_frame_id>
    </sensor>
  </gazebo>
</robot>

